[0m02:35:08.783209 [debug] [MainThread]: Sending event: {'category': 'dbt', 'action': 'invocation', 'label': 'start', 'context': [<snowplow_tracker.self_describing_json.SelfDescribingJson object at 0x000001C945AB4550>, <snowplow_tracker.self_describing_json.SelfDescribingJson object at 0x000001C943CF5910>, <snowplow_tracker.self_describing_json.SelfDescribingJson object at 0x000001C945AB4BD0>]}


============================== 02:35:08.789713 | 22ce5530-dd7d-47cf-a493-9607f3ff1608 ==============================
[0m02:35:08.789713 [info ] [MainThread]: Running with dbt=1.7.11
[0m02:35:08.790215 [debug] [MainThread]: running dbt with arguments {'printer_width': '80', 'indirect_selection': 'eager', 'write_json': 'True', 'log_cache_events': 'False', 'partial_parse': 'True', 'cache_selected_only': 'False', 'warn_error': 'None', 'fail_fast': 'False', 'debug': 'False', 'log_path': 'logs', 'version_check': 'True', 'profiles_dir': 'C:\\Users\\Sami Kaan\\.dbt', 'use_colors': 'True', 'use_experimental_parser': 'False', 'no_print': 'None', 'quiet': 'False', 'log_format': 'default', 'invocation_command': 'dbt init', 'introspect': 'True', 'static_parser': 'True', 'target_path': 'None', 'warn_error_options': 'WarnErrorOptions(include=[], exclude=[])', 'send_anonymous_usage_stats': 'True'}
[0m02:35:08.790215 [warn ] [MainThread]: [ConfigFolderDirectory]: Unable to parse dict {'dir': WindowsPath('C:/Users/Sami Kaan/.dbt')}
[0m02:35:08.791222 [info ] [MainThread]: Creating dbt configuration folder at 
[0m02:36:12.123085 [debug] [MainThread]: Starter project path: c:\Users\Sami Kaan\Desktop\projects\.venv\Lib\site-packages\dbt\include\starter_project
[0m02:36:12.150364 [info ] [MainThread]: 
Your new dbt project "medallion_dbt_spark" was created!

For more information on how to configure the profiles.yml file,
please consult the dbt documentation here:

  https://docs.getdbt.com/docs/configure-your-profile

One more thing:

Need help? Don't hesitate to reach out to us via GitHub issues or on Slack:

  https://community.getdbt.com/

Happy modeling!

[0m02:36:12.151365 [info ] [MainThread]: Setting up your profile.
[0m02:39:04.571796 [info ] [MainThread]: Profile medallion_dbt_spark written to C:\Users\Sami Kaan\.dbt\profiles.yml using target's profile_template.yml and your supplied values. Run 'dbt debug' to validate the connection.
[0m02:39:04.573853 [debug] [MainThread]: Command `dbt init` succeeded at 02:39:04.573853 after 235.81 seconds
[0m02:39:04.574554 [debug] [MainThread]: Sending event: {'category': 'dbt', 'action': 'invocation', 'label': 'end', 'context': [<snowplow_tracker.self_describing_json.SelfDescribingJson object at 0x000001C945AC7D90>, <snowplow_tracker.self_describing_json.SelfDescribingJson object at 0x000001C945AC7E50>, <snowplow_tracker.self_describing_json.SelfDescribingJson object at 0x000001C93FED5610>]}
[0m02:39:04.574554 [debug] [MainThread]: Flushing usage events
[0m02:39:27.713258 [debug] [MainThread]: Sending event: {'category': 'dbt', 'action': 'invocation', 'label': 'start', 'context': [<snowplow_tracker.self_describing_json.SelfDescribingJson object at 0x0000015BEB5AF9D0>, <snowplow_tracker.self_describing_json.SelfDescribingJson object at 0x0000015BEB5BA550>, <snowplow_tracker.self_describing_json.SelfDescribingJson object at 0x0000015BEB5B9190>]}


============================== 02:39:27.715767 | b84245ce-84bf-4508-a384-7b9ebb7aaabc ==============================
[0m02:39:27.715767 [info ] [MainThread]: Running with dbt=1.7.11
[0m02:39:27.715767 [debug] [MainThread]: running dbt with arguments {'printer_width': '80', 'indirect_selection': 'eager', 'log_cache_events': 'False', 'write_json': 'True', 'partial_parse': 'True', 'cache_selected_only': 'False', 'warn_error': 'None', 'debug': 'False', 'fail_fast': 'False', 'log_path': 'logs', 'profiles_dir': 'C:\\Users\\Sami Kaan\\.dbt', 'version_check': 'True', 'use_colors': 'True', 'use_experimental_parser': 'False', 'no_print': 'None', 'quiet': 'False', 'log_format': 'default', 'invocation_command': 'dbt debug', 'static_parser': 'True', 'warn_error_options': 'WarnErrorOptions(include=[], exclude=[])', 'target_path': 'None', 'introspect': 'True', 'send_anonymous_usage_stats': 'True'}
[0m02:39:27.716768 [info ] [MainThread]: dbt version: 1.7.11
[0m02:39:27.716768 [info ] [MainThread]: python version: 3.11.9
[0m02:39:27.716768 [info ] [MainThread]: python path: c:\Users\Sami Kaan\Desktop\projects\.venv\Scripts\python.exe
[0m02:39:27.717768 [info ] [MainThread]: os info: Windows-10-10.0.22631-SP0
[0m02:39:28.362039 [info ] [MainThread]: Using profiles dir at C:\Users\Sami Kaan\.dbt
[0m02:39:28.363039 [info ] [MainThread]: Using profiles.yml file at C:\Users\Sami Kaan\.dbt\profiles.yml
[0m02:39:28.363487 [info ] [MainThread]: Using dbt_project.yml file at C:\Users\Sami Kaan\Desktop\projects\Python\dbt_project.yml
[0m02:39:28.363487 [info ] [MainThread]: adapter type: databricks
[0m02:39:28.364509 [info ] [MainThread]: adapter version: 1.7.13
[0m02:39:28.364509 [info ] [MainThread]: Configuration:
[0m02:39:28.365492 [info ] [MainThread]:   profiles.yml file [[32mOK found and valid[0m]
[0m02:39:28.365492 [info ] [MainThread]:   dbt_project.yml file [[31mERROR not found[0m]
[0m02:39:28.365492 [info ] [MainThread]: Required dependencies:
[0m02:39:28.366736 [debug] [MainThread]: Executing "git --help"
[0m02:39:28.368736 [info ] [MainThread]:  - git [[31mERROR[0m]

[0m02:39:28.370239 [info ] [MainThread]: Connection:
[0m02:39:28.370372 [info ] [MainThread]:   host: https://adb-4446208468797596.16.azuredatabricks.net
[0m02:39:28.370372 [info ] [MainThread]:   http_path: sql/protocolv1/o/4446208468797596/0415-170011-gythive5
[0m02:39:28.371372 [info ] [MainThread]:   catalog: hive_metastore
[0m02:39:28.371372 [info ] [MainThread]:   schema: saleslt
[0m02:39:28.371372 [info ] [MainThread]: Registered adapter: databricks=1.7.13
[0m02:39:28.372373 [debug] [MainThread]: Databricks adapter: conn: 1492989009232: Creating DatabricksDBTConnection sess: None, name: debug, idle: 0s, acqrelcnt: 0, lang: None, thrd: (24892, 8752), cmpt: ``, lut: None
[0m02:39:28.374462 [debug] [MainThread]: Acquiring new databricks connection 'debug'
[0m02:39:28.374462 [debug] [MainThread]: Databricks adapter: Thread (24892, 8752) using default compute resource.
[0m02:39:28.374462 [debug] [MainThread]: Databricks adapter: conn: 1492989009232: _acquire sess: None, name: debug, idle: 0.0s, acqrelcnt: 1, lang: None, thrd: (24892, 8752), cmpt: ``, lut: 1713227968.3744621
[0m02:39:28.374462 [debug] [MainThread]: Databricks adapter: conn: 1492989009232: get_thread_connection: sess: None, name: debug, idle: 0.0s, acqrelcnt: 1, lang: None, thrd: (24892, 8752), cmpt: ``, lut: 1713227968.3744621
[0m02:39:28.374462 [debug] [MainThread]: Databricks adapter: conn: 1492989009232: idle check connection: sess: None, name: debug, idle: 0.0s, acqrelcnt: 1, lang: None, thrd: (24892, 8752), cmpt: ``, lut: 1713227968.3744621
[0m02:39:28.375967 [debug] [MainThread]: Using databricks connection "debug"
[0m02:39:28.375967 [debug] [MainThread]: On debug: select 1 as id
[0m02:39:28.375967 [debug] [MainThread]: Opening a new connection, currently in state init
[0m02:39:31.107422 [debug] [MainThread]: Databricks adapter: Error while running:
select 1 as id
[0m02:39:31.108085 [debug] [MainThread]: Databricks adapter: Database Error
  HTTPSConnectionPool(host='https', port=None): Max retries exceeded with url: //adb-4446208468797596.16.azuredatabricks.net:443/sql/protocolv1/o/4446208468797596/0415-170011-gythive5 (Caused by NewConnectionError('<urllib3.connection.HTTPSConnection object at 0x0000015B9D1756D0>: Failed to establish a new connection: [Errno 11001] getaddrinfo failed'))
[0m02:39:31.108085 [debug] [MainThread]: Databricks adapter: conn: 1492989009232: _release sess: None, name: debug, idle: 0.0s, acqrelcnt: 0, lang: None, thrd: (24892, 8752), cmpt: ``, lut: 1713227971.1080854
[0m02:39:31.109106 [info ] [MainThread]:   Connection test: [[31mERROR[0m]

[0m02:39:31.109106 [info ] [MainThread]: [31m3 checks failed:[0m
[0m02:39:31.109106 [info ] [MainThread]: Project loading failed for the following reason:
 project path <C:\Users\Sami Kaan\Desktop\projects\Python\dbt_project.yml> not found

[0m02:39:31.109106 [info ] [MainThread]: Error from git --help: Could not find command, ensure it is in the user's PATH and that the user has permissions to run it: "git"

[0m02:39:31.110613 [info ] [MainThread]: dbt was unable to connect to the specified database.
The database returned the following error:

  >Runtime Error
  Database Error
    HTTPSConnectionPool(host='https', port=None): Max retries exceeded with url: //adb-4446208468797596.16.azuredatabricks.net:443/sql/protocolv1/o/4446208468797596/0415-170011-gythive5 (Caused by NewConnectionError('<urllib3.connection.HTTPSConnection object at 0x0000015B9D1756D0>: Failed to establish a new connection: [Errno 11001] getaddrinfo failed'))

Check your database credentials and try again. For more information, visit:
https://docs.getdbt.com/docs/configure-your-profile


[0m02:39:31.112543 [debug] [MainThread]: Command `dbt debug` failed at 02:39:31.111940 after 3.44 seconds
[0m02:39:31.112543 [debug] [MainThread]: Connection 'debug' was properly closed.
[0m02:39:31.113054 [debug] [MainThread]: On debug: No close available on handle
[0m02:39:31.113054 [debug] [MainThread]: Sending event: {'category': 'dbt', 'action': 'invocation', 'label': 'end', 'context': [<snowplow_tracker.self_describing_json.SelfDescribingJson object at 0x0000015BEB5BB290>, <snowplow_tracker.self_describing_json.SelfDescribingJson object at 0x0000015BEB3DEF10>, <snowplow_tracker.self_describing_json.SelfDescribingJson object at 0x0000015BFF6A0410>]}
[0m02:39:31.113054 [debug] [MainThread]: Flushing usage events
[0m02:48:39.977579 [debug] [MainThread]: Sending event: {'category': 'dbt', 'action': 'invocation', 'label': 'start', 'context': [<snowplow_tracker.self_describing_json.SelfDescribingJson object at 0x000001B20B452390>, <snowplow_tracker.self_describing_json.SelfDescribingJson object at 0x000001B20CBB74D0>, <snowplow_tracker.self_describing_json.SelfDescribingJson object at 0x000001B20CBB4650>]}


============================== 02:48:39.979578 | a4f105dc-5cf1-409c-b783-989888ad671d ==============================
[0m02:48:39.979578 [info ] [MainThread]: Running with dbt=1.7.11
[0m02:48:39.980579 [debug] [MainThread]: running dbt with arguments {'printer_width': '80', 'indirect_selection': 'eager', 'write_json': 'True', 'log_cache_events': 'False', 'partial_parse': 'True', 'cache_selected_only': 'False', 'warn_error': 'None', 'fail_fast': 'False', 'version_check': 'True', 'log_path': 'C:\\Users\\Sami Kaan\\Desktop\\projects\\Python\\logs', 'profiles_dir': 'C:\\Users\\Sami Kaan\\.dbt', 'debug': 'False', 'use_colors': 'True', 'use_experimental_parser': 'False', 'no_print': 'None', 'quiet': 'False', 'warn_error_options': 'WarnErrorOptions(include=[], exclude=[])', 'introspect': 'True', 'static_parser': 'True', 'invocation_command': 'dbt debug', 'target_path': 'None', 'log_format': 'default', 'send_anonymous_usage_stats': 'True'}
[0m02:48:39.980579 [info ] [MainThread]: dbt version: 1.7.11
[0m02:48:39.981579 [info ] [MainThread]: python version: 3.11.9
[0m02:48:39.981579 [info ] [MainThread]: python path: c:\Users\Sami Kaan\Desktop\projects\.venv\Scripts\python.exe
[0m02:48:39.981579 [info ] [MainThread]: os info: Windows-10-10.0.22631-SP0
[0m02:48:40.621796 [info ] [MainThread]: Using profiles dir at C:\Users\Sami Kaan\.dbt
[0m02:48:40.621796 [info ] [MainThread]: Using profiles.yml file at C:\Users\Sami Kaan\.dbt\profiles.yml
[0m02:48:40.621796 [info ] [MainThread]: Using dbt_project.yml file at C:\Users\Sami Kaan\Desktop\projects\Python\dbt_project.yml
[0m02:48:40.623320 [info ] [MainThread]: adapter type: databricks
[0m02:48:40.623320 [info ] [MainThread]: adapter version: 1.7.13
[0m02:48:40.664563 [info ] [MainThread]: Configuration:
[0m02:48:40.664563 [info ] [MainThread]:   profiles.yml file [[32mOK found and valid[0m]
[0m02:48:40.665566 [info ] [MainThread]:   dbt_project.yml file [[32mOK found and valid[0m]
[0m02:48:40.665566 [info ] [MainThread]: Required dependencies:
[0m02:48:40.665566 [debug] [MainThread]: Executing "git --help"
[0m02:48:40.669073 [info ] [MainThread]:  - git [[31mERROR[0m]

[0m02:48:40.669073 [info ] [MainThread]: Connection:
[0m02:48:40.670146 [info ] [MainThread]:   host: https://adb-4446208468797596.16.azuredatabricks.net
[0m02:48:40.670146 [info ] [MainThread]:   http_path: sql/protocolv1/o/4446208468797596/0415-170011-gythive5
[0m02:48:40.670146 [info ] [MainThread]:   catalog: hive_metastore
[0m02:48:40.671147 [info ] [MainThread]:   schema: saleslt
[0m02:48:40.671147 [info ] [MainThread]: Registered adapter: databricks=1.7.13
[0m02:48:40.672147 [debug] [MainThread]: Databricks adapter: conn: 1865063358480: Creating DatabricksDBTConnection sess: None, name: debug, idle: 0s, acqrelcnt: 0, lang: None, thrd: (18588, 9936), cmpt: ``, lut: None
[0m02:48:40.672147 [debug] [MainThread]: Acquiring new databricks connection 'debug'
[0m02:48:40.672147 [debug] [MainThread]: Databricks adapter: Thread (18588, 9936) using default compute resource.
[0m02:48:40.673147 [debug] [MainThread]: Databricks adapter: conn: 1865063358480: _acquire sess: None, name: debug, idle: 0.0s, acqrelcnt: 1, lang: None, thrd: (18588, 9936), cmpt: ``, lut: 1713228520.6731474
[0m02:48:40.673147 [debug] [MainThread]: Databricks adapter: conn: 1865063358480: get_thread_connection: sess: None, name: debug, idle: 0.0s, acqrelcnt: 1, lang: None, thrd: (18588, 9936), cmpt: ``, lut: 1713228520.6731474
[0m02:48:40.673147 [debug] [MainThread]: Databricks adapter: conn: 1865063358480: idle check connection: sess: None, name: debug, idle: 0.0s, acqrelcnt: 1, lang: None, thrd: (18588, 9936), cmpt: ``, lut: 1713228520.6731474
[0m02:48:40.673147 [debug] [MainThread]: Using databricks connection "debug"
[0m02:48:40.673147 [debug] [MainThread]: On debug: select 1 as id
[0m02:48:40.674651 [debug] [MainThread]: Opening a new connection, currently in state init
[0m02:48:43.397732 [debug] [MainThread]: Databricks adapter: Error while running:
select 1 as id
[0m02:48:43.397732 [debug] [MainThread]: Databricks adapter: Database Error
  HTTPSConnectionPool(host='https', port=None): Max retries exceeded with url: //adb-4446208468797596.16.azuredatabricks.net:443/sql/protocolv1/o/4446208468797596/0415-170011-gythive5 (Caused by NewConnectionError('<urllib3.connection.HTTPSConnection object at 0x000001B23E752310>: Failed to establish a new connection: [Errno 11001] getaddrinfo failed'))
[0m02:48:43.398732 [debug] [MainThread]: Databricks adapter: conn: 1865063358480: _release sess: None, name: debug, idle: 0.0s, acqrelcnt: 0, lang: None, thrd: (18588, 9936), cmpt: ``, lut: 1713228523.398733
[0m02:48:43.398732 [info ] [MainThread]:   Connection test: [[31mERROR[0m]

[0m02:48:43.399733 [info ] [MainThread]: [31m2 checks failed:[0m
[0m02:48:43.400236 [info ] [MainThread]: Error from git --help: Could not find command, ensure it is in the user's PATH and that the user has permissions to run it: "git"

[0m02:48:43.400236 [info ] [MainThread]: dbt was unable to connect to the specified database.
The database returned the following error:

  >Runtime Error
  Database Error
    HTTPSConnectionPool(host='https', port=None): Max retries exceeded with url: //adb-4446208468797596.16.azuredatabricks.net:443/sql/protocolv1/o/4446208468797596/0415-170011-gythive5 (Caused by NewConnectionError('<urllib3.connection.HTTPSConnection object at 0x000001B23E752310>: Failed to establish a new connection: [Errno 11001] getaddrinfo failed'))

Check your database credentials and try again. For more information, visit:
https://docs.getdbt.com/docs/configure-your-profile


[0m02:48:43.402239 [debug] [MainThread]: Command `dbt debug` failed at 02:48:43.402239 after 3.46 seconds
[0m02:48:43.402239 [debug] [MainThread]: Connection 'debug' was properly closed.
[0m02:48:43.402239 [debug] [MainThread]: On debug: No close available on handle
[0m02:48:43.402239 [debug] [MainThread]: Sending event: {'category': 'dbt', 'action': 'invocation', 'label': 'end', 'context': [<snowplow_tracker.self_describing_json.SelfDescribingJson object at 0x000001B20CE34C90>, <snowplow_tracker.self_describing_json.SelfDescribingJson object at 0x000001B20CBADC50>, <snowplow_tracker.self_describing_json.SelfDescribingJson object at 0x000001B20C885810>]}
[0m02:48:43.403238 [debug] [MainThread]: Flushing usage events
[0m03:04:58.112987 [debug] [MainThread]: Sending event: {'category': 'dbt', 'action': 'invocation', 'label': 'start', 'context': [<snowplow_tracker.self_describing_json.SelfDescribingJson object at 0x000001E42C6AE3D0>, <snowplow_tracker.self_describing_json.SelfDescribingJson object at 0x000001E42C6B8610>, <snowplow_tracker.self_describing_json.SelfDescribingJson object at 0x000001E42C6BB510>]}


============================== 03:04:58.115986 | 7cff6b66-5d9c-4715-809a-29aa1dc09af5 ==============================
[0m03:04:58.115986 [info ] [MainThread]: Running with dbt=1.7.11
[0m03:04:58.115986 [debug] [MainThread]: running dbt with arguments {'printer_width': '80', 'indirect_selection': 'eager', 'write_json': 'True', 'log_cache_events': 'False', 'partial_parse': 'True', 'cache_selected_only': 'False', 'warn_error': 'None', 'version_check': 'True', 'fail_fast': 'False', 'log_path': 'logs', 'debug': 'False', 'profiles_dir': 'C:\\Users\\Sami Kaan\\.dbt', 'use_colors': 'True', 'use_experimental_parser': 'False', 'no_print': 'None', 'quiet': 'False', 'log_format': 'default', 'introspect': 'True', 'static_parser': 'True', 'invocation_command': 'dbt debug', 'target_path': 'None', 'warn_error_options': 'WarnErrorOptions(include=[], exclude=[])', 'send_anonymous_usage_stats': 'True'}
[0m03:04:58.115986 [info ] [MainThread]: dbt version: 1.7.11
[0m03:04:58.117490 [info ] [MainThread]: python version: 3.11.9
[0m03:04:58.117739 [info ] [MainThread]: python path: c:\Users\Sami Kaan\Desktop\projects\.venv\Scripts\python.exe
[0m03:04:58.117739 [info ] [MainThread]: os info: Windows-10-10.0.22631-SP0
[0m03:04:58.853764 [info ] [MainThread]: Using profiles dir at C:\Users\Sami Kaan\.dbt
[0m03:04:58.855673 [info ] [MainThread]: Using profiles.yml file at C:\Users\Sami Kaan\.dbt\profiles.yml
[0m03:04:58.856239 [info ] [MainThread]: Using dbt_project.yml file at C:\Users\Sami Kaan\Desktop\projects\Python\dbt_project.yml
[0m03:04:58.856744 [info ] [MainThread]: adapter type: databricks
[0m03:04:58.856744 [info ] [MainThread]: adapter version: 1.7.13
[0m03:04:58.856744 [info ] [MainThread]: Configuration:
[0m03:04:58.857748 [info ] [MainThread]:   profiles.yml file [[32mOK found and valid[0m]
[0m03:04:58.857748 [info ] [MainThread]:   dbt_project.yml file [[31mERROR not found[0m]
[0m03:04:58.858748 [info ] [MainThread]: Required dependencies:
[0m03:04:58.858748 [debug] [MainThread]: Executing "git --help"
[0m03:04:58.861747 [info ] [MainThread]:  - git [[31mERROR[0m]

[0m03:04:58.862747 [info ] [MainThread]: Connection:
[0m03:04:58.862747 [info ] [MainThread]:   host: adb-4446208468797596.16.azuredatabricks.net
[0m03:04:58.862747 [info ] [MainThread]:   http_path: sql/protocolv1/o/4446208468797596/0415-170011-gythive5
[0m03:04:58.863834 [info ] [MainThread]:   catalog: hive_metastore
[0m03:04:58.863834 [info ] [MainThread]:   schema: saleslt
[0m03:04:58.863834 [info ] [MainThread]: Registered adapter: databricks=1.7.13
[0m03:04:58.865337 [debug] [MainThread]: Databricks adapter: conn: 2080340603536: Creating DatabricksDBTConnection sess: None, name: debug, idle: 0s, acqrelcnt: 0, lang: None, thrd: (28004, 4448), cmpt: ``, lut: None
[0m03:04:58.865337 [debug] [MainThread]: Acquiring new databricks connection 'debug'
[0m03:04:58.866340 [debug] [MainThread]: Databricks adapter: Thread (28004, 4448) using default compute resource.
[0m03:04:58.866340 [debug] [MainThread]: Databricks adapter: conn: 2080340603536: _acquire sess: None, name: debug, idle: 0.0s, acqrelcnt: 1, lang: None, thrd: (28004, 4448), cmpt: ``, lut: 1713229498.8663406
[0m03:04:58.866340 [debug] [MainThread]: Databricks adapter: conn: 2080340603536: get_thread_connection: sess: None, name: debug, idle: 0.0s, acqrelcnt: 1, lang: None, thrd: (28004, 4448), cmpt: ``, lut: 1713229498.8663406
[0m03:04:58.867339 [debug] [MainThread]: Databricks adapter: conn: 2080340603536: idle check connection: sess: None, name: debug, idle: 0.0s, acqrelcnt: 1, lang: None, thrd: (28004, 4448), cmpt: ``, lut: 1713229498.8663406
[0m03:04:58.867339 [debug] [MainThread]: Using databricks connection "debug"
[0m03:04:58.867339 [debug] [MainThread]: On debug: select 1 as id
[0m03:04:58.867339 [debug] [MainThread]: Opening a new connection, currently in state init
[0m03:04:59.580268 [debug] [MainThread]: Databricks adapter: conn: 2080340603536: session opened sess: a107a585-ecc6-4b79-90c6-84ebe5aa7d50, name: debug, idle: 0.0s, acqrelcnt: 1, lang: None, thrd: (28004, 4448), cmpt: ``, lut: 1713229499.5802689
[0m03:05:02.081343 [debug] [MainThread]: SQL status: OK in 3.2100000381469727 seconds
[0m03:05:02.082344 [debug] [MainThread]: Databricks adapter: conn: 2080340603536: _release sess: a107a585-ecc6-4b79-90c6-84ebe5aa7d50, name: debug, idle: 0.0s, acqrelcnt: 0, lang: None, thrd: (28004, 4448), cmpt: ``, lut: 1713229502.0823448
[0m03:05:02.082344 [info ] [MainThread]:   Connection test: [[32mOK connection ok[0m]

[0m03:05:02.093847 [info ] [MainThread]: [31m2 checks failed:[0m
[0m03:05:02.093847 [info ] [MainThread]: Project loading failed for the following reason:
 project path <C:\Users\Sami Kaan\Desktop\projects\Python\dbt_project.yml> not found

[0m03:05:02.094847 [info ] [MainThread]: Error from git --help: Could not find command, ensure it is in the user's PATH and that the user has permissions to run it: "git"

[0m03:05:02.096023 [debug] [MainThread]: Command `dbt debug` failed at 03:05:02.096023 after 4.02 seconds
[0m03:05:02.096023 [debug] [MainThread]: Connection 'debug' was properly closed.
[0m03:05:02.096023 [debug] [MainThread]: On debug: Close
[0m03:05:02.547064 [debug] [MainThread]: Sending event: {'category': 'dbt', 'action': 'invocation', 'label': 'end', 'context': [<snowplow_tracker.self_describing_json.SelfDescribingJson object at 0x000001E42C72BC10>, <snowplow_tracker.self_describing_json.SelfDescribingJson object at 0x000001E45DF27A50>, <snowplow_tracker.self_describing_json.SelfDescribingJson object at 0x000001E42C185B50>]}
[0m03:05:02.547650 [debug] [MainThread]: Flushing usage events
